<!DOCTYPE html>
<html>
  <head>
    <meta charset="utf-8">
    <title>promise</title>
  </head>
  <body>
    <script>
      window.onload = function(){
        // 1、异步、同步、串行、并行
        // 2、Promise既是一个对象也是一个构造函数
        // 3、查看promise的api: console.dir(Promise);
        // 4、传统的异步有哪些？如何串行和并行执行
        // 5、同步、微异步、异步的执行步骤
        // 6、promise有哪些特征
        // 7、api详解
        // javascript语言本身是单线程的。同一时刻，有且仅有一处代码正在执行。包括setTime的那两个函数也是如此。所有涉及到异步的方法和函数都是由浏览器的另一个线程去执行的，程序员所能控制的"另一个线程"也仅限于这些方法。

        // let promise = new Promise(function(resolve,reject){
        //   // 在这里执行异步操作...
        //   if(/*异步操作成功*/){
        //       resolve(success);
        //   }else{
        //       reject(error);
        //   }
        // });
        // 等价于
        // let promise = new Promise((resolve,reject) => {
        //   // 在这里执行异步操作...
        //   if(/*异步操作成功*/){
        //       resolve(success);
        //   }else{
        //       reject(error);
        //   }
        // });

        // promise.then(function(success){
        //   // 异步操作成功在这里执行...
        //   // 对应于上面的resolve(success)方法
        // },function(error){
        //   // 异步操作失败在这里执行...
        //   // 对应于上面的reject(error)方法
        // })
        // // 上面的写法还可以写成这样（一般推荐使用下面这种写法）
        // promise.then(function(success){
        //   // 异步操作成功在这里执行...
        //   // 对应于上面的resolve(success)方法
        // }).catch(function(error){
        //   // 异步操作失败在这里执行...
        //   // 对应于上面的reject(error)方法
        // });


        // 宏任务
        // new Promise((resolve,reject) => {
        //   console.log('new Promise');
        //   // Promise.resolve()属于微任务
        //   resolve('resolve');
        // }).then((success) => {
        //   console.log(success);
        // });
        //
        // // 宏任务
        // setTimeout(() => console.log('setTimeout'),0);
        //
        // // 宏任务
        // console.log('console.log');
        // 控制台输出的结果
        // new Promise
        // console.log
        // resolve
        // setTimeout

        // 如果不设置回调函数，Promise内部抛出的错误，不会反应到外部
        // createPromise("P1",0).then((success) => {
        //   console.log(success);
        // });
        //
        // console.log('console log');
        //
        // createPromise("p2",1).then((success) => {
        //   console.log(success);
        // });
        // 控制台打印结果: 由于p1和p2属于异步执行，所以他们的结果打印出来的顺序不固定
        // console log
        // p2 ok
        // Uncaught (in promise) P1 fail

        // 抛错具有冒泡性质,会一直往外抛,直到被捕获为止
        // createPromise("p1",0).then(function(success){
        //   console.log(success);
        //   return createPromise("p2",0);
        // }).then(function(success){
        //   console.log(success);
        //   return createPromise("p3",0);
        // }).catch(function(error){
        //   console.log(error); // p1 fail
        // })

        // Promise状态一旦确定，就不会再变，任何时候都可以得到这个结果
        // new Promise((resolve,reject) => {
        //   resolve('resolve');
        //   reject('reject');
        //   //throw new Error("出错了");
        // }).then((success) => {
        //   console.log(success); // resolve
        // },(error) => {
        //   console.log(error);
        // });

        // then可以很好的解决了异步串行的操作，避免了传统异步层层嵌套的问题
        // 传统的异步串行操作,会层层嵌套使用
        // $.ajax({
        //   url: "...",
        //   success: function(data){
        //     $.ajax({
        //       url: "***",
        //       data: data,
        //       success: function(data){
        //         $.ajax({
        //           url: "---",
        //           data: data,
        //           success: function(data){
        //             ...
        //           }
        //         });
        //       }
        //     });
        //   }
        // });

        // 用Promise.prototype.then执行异步串行操作，代码更简洁直观
        // createPromise("p1",1).then(function(success){
        //   console.log("正在执行 " + success);
        //   return createPromise("p2",1);
        // }).then(function(success){
        //   console.log("正在执行 " + success);
        //   return createPromise("p3",1);
        // }).then(function(success){
        //   console.log("正在执行 " + success);
        // });
        // 正在执行 p1 ok
        // 正在执行 p2 ok
        // 正在执行 p3 ok


        // 生成Promise对象
        function createPromise(p,arg){
          return new Promise((resolve,reject) => {
            setTimeout(() => {
                if(arg === 0){
                  reject(p+' fail');
                }else{
                  resolve(p+ " ok");
                }
            },0);
          });
        }
        // 两个Promise都成功，返回异步操作数组结果
        // Promise
        //   .all([createPromise("p1",1),createPromise("p2",1)])
        //   .then(function(results){
        //     console.log(results); // (2) ["p1 ok", "p2 ok"]
        //   });
        // // 两个Promise都失败，只返回第一失败的结果信息
        // Promise
        //   .all([createPromise("p1",0),createPromise("p2",0)])
        //   .then(function(results){
        //     console.log(results);
        //   }).catch(function(error){
        //     console.log(error); // p1 fail
        //   });
        //

        // Promise
        //   .race([createPromise("p1",1),createPromise("p2",1)])
        //   .then(function(results){
        //     console.log(results); // p1 ok
        //   });
        //
        // Promise
        //   .race([createPromise("p1",0),createPromise("p2",1)])
        //   .then(function(results){
        //     console.log(results);
        //   }).catch(function(error){
        //     console.log(error); // p1 fail
        //   });
        //

        // 无法捕获后面抛出的错误
        // createPromise("p1", 1).then(function(success){
        //   console.log(success); // p1 ok
        //   return createPromise("p2",1);
        // }).catch(function(error){
        //   console.log(error); // 这里无法捕获到p3抛出的错误
        // }).then(function(success){
        //   console.log(success); // p2 ok
        //   return createPromise("p3",0); // Uncaught (in promise) p3 fail
        // });
        //
        // createPromise("p1", 1).then(function(success){
        //   console.log(success); // p1 ok
        //   return createPromise("p2",1);
        // },function(error){
        //   console.log(error);// 这里无法捕获到p3抛出的错误
        // }).then(function(success){
        //   console.log(success); // p2 ok
        //   return createPromise("p3",0); // Uncaught (in promise) p3 fail
        // });

        // 如果状态一旦确定,就不会再变.要么执行resolve要么执行reject
        // let promise = new Promise(function(resolve, reject) {
        //   resolve('ok');
        //   throw new Error('test');
        // });
        //
        // promise.then(function(success){
        //    console.log(success); // ok
        // }).catch(function(error){
        //    console.log(error); // 不会打印,只会有一种状态
        // });

        // createPromise("p1", 0).then(function(success){
        //   console.log("第一个异步成功回调: "+success);
        //   return createPromise("p2", 0);
        // });//Uncaught (in promise) p1 fail

        // finally的用法,不管前面结果怎么样,都会执行finally这个方法
        // createPromise("p1",0).then(function(success){
        //   console.log(success);
        // }).catch(function(error){
        //   console.log(error); // p1 fail
        // }).finally(function(){
        //   console.log("finally"); // finally
        // });
        // createPromise("p1",1).then(function(success){
        //   console.log(success); // p1 ok
        // }).catch(function(error){
        //   console.log(error);
        // }).finally(function(){
        //   console.log("finally"); // finally
        // });

        // Promise.resolve()代码等价
        //let successPromise = Promise.resolve('ok'); 等同于以下代码
        // let successPromise = new Promise(function(resolve,reject){
        //     resolve('ok');
        // });
        // successPromise.then(function(success){
        //   console.log(success); // ok
        // });

        // 当resolve()参数为Promise实例
        // const p1 = new Promise(function (resolve, reject) {
        //   setTimeout(() => reject(new Error('fail')), 3000)
        // });
        //
        // const p2 = new Promise(function (resolve, reject) {
        //   setTimeout(() => resolve(p1), 1000)
        // });
        //
        // p2.then(success => console.log(success))
        //   .catch(error => console.log(error))
        // Error: fail  at setTimeout (promise.html:255)

        // 上面代码中，p1是一个 Promise，3 秒之后变为rejected。
        // p2的状态在 1 秒之后改变，resolve方法返回的是p1。
        // 由于p2返回的是另一个 Promise，导致p2自己的状态无效了，
        // 由p1的状态决定p2的状态。所以，后面的then语句都变成针对后者（p1）。
        // 又过了 2 秒，p1变为rejected，导致触发catch方法指定的回调函数。

        // Promise.reject()代码等价
        // let errorPromise = Promise.reject('fail'); 等同于下面的代码
        // let errorPromise = new Promise(function(resolve,reject){
        //    reject('fail');
        // });
        // errorPromise.then(function(success){
        //   console.log(success);
        // }).catch(function(error){
        //   console.log(error); // fail
        // });

        // 调用resolve或reject方法并不会终结后面函数的执行
        // new Promise((resolve, reject) => {
        //    console.log(1);
        //    resolve('ok');
        //    console.log(2);
        // }).then(success => {
        //    console.log(success);
        // });
        // 控制打印结果：
        // 1
        // 2
        // ok

        // 一般来说，调用resolve或reject以后，Promise 的使命就完成了，
        // 后继操作应该放到then方法里面，而不应该直接写在resolve或reject的后面
        // new Promise((resolve, reject) => {
        //   console.log(1);
        //   return resolve('ok');
        //   console.log(2);
        // }).then(success => {
        //   console.log(success);
        // });
        // 控制打印结果：
        // 1
        // ok


        // catch的写法一
        // new Promise((resolve, reject) => {
        //    try {
        //      throw new Error('fail');
        //    } catch(e) {
        //      reject(e);
        //    }
        // }).catch(error => {
        //    console.log(error); // Error: fail
        // });

        // catch的写法二
        // new Promise((resolve, reject) => {
        //    reject(new Error('fail'));
        // }).catch(error => {
        //    console.log(error); // Error: fail
        // });

        // 加载图片
        function loadImg(url){
          return new Promise((resolve,reject) => {
            let img = document.createElement("img");
            img.src = url;
            img.style.width = "800px";
            img.style.height = "400px";
            img.onload = function(){
              resolve(img);
            }
            img.onerror = function(error){
              reject('img load is error');
            }
          });
        }
        // 显示多张图片
        function showImgs(imgs){
          imgs.forEach(function(item){
            document.body.appendChild(item);
          });
        }
        // 显示一张图
        function showImg(img){
            document.body.appendChild(img);
        }

        // Promise.all([
        //   loadImg("https://images.unsplash.com/photo-1535025639604-9a804c092faa?ixlib=rb-0.3.5&ixid=eyJhcHBfaWQiOjEyMDd9&s=6cb0ceb620f241feb2f859e273634393&w=1000&q=80"),
        //   loadImg("https://images.unsplash.com/photo-1535064297005-f2b066183faa?ixlib=rb-0.3.5&ixid=eyJhcHBfaWQiOjEyMDd9&s=dcc833176f802657964d7e562c492843&w=1000&q=80"),
        //   //loadImg("http://images.unsplash.com/photo-1535064297005?ixlib=rb-0.3.5&ixid=eyJhcHBfaWQiOjEyMDd9&s=dcc833176f802657964d7e562c492843&w=1000&q=80")
        // ]).then(success => {
        //   console.log(success); // 只有所有的图片都加载出来了，这里才会被执行
        //   showImgs(success);
        // }).catch(error => {
        //   console.log(error); // 只要有一张图片走reject方法，这里就会被执行
        // });

        Promise.race([
          loadImg("http://images.unsplash.com/photo-1535064297005?ixlib=rb-0.3.5&ixid=eyJhcHBfaWQiOjEyMDd9&s=dcc833176f802657964d7e562c492843&w=1000&q=80"),
          loadImg("https://images.unsplash.com/photo-1535025639604-9a804c092faa?ixlib=rb-0.3.5&ixid=eyJhcHBfaWQiOjEyMDd9&s=6cb0ceb620f241feb2f859e273634393&w=1000&q=80"),
          loadImg("https://images.unsplash.com/photo-1535064297005-f2b066183faa?ixlib=rb-0.3.5&ixid=eyJhcHBfaWQiOjEyMDd9&s=dcc833176f802657964d7e562c492843&w=1000&q=80")
        ]).then(success => {
          console.log(success); //谁先加载成功就打印谁，后面要是再加载出错误的图片也不会被捕获了
          showImg(success);
        }).catch(error => {
          console.log(error); // 如果先加载的是错误的图片，则这里会打印
        });

        // 如果Promise.all的Promise实例参数自己定义了catch方法，那么它一旦被rejected，
        // 就不会触发Promise.all()的catch方法了
        // const p1 = new Promise((resolve, reject) => {
        //   resolve('ok');
        // }).then(result => result).catch(e => e);
        //
        // const p2 = new Promise((resolve, reject) => {
        //   throw new Error('报错了');
        // }).then(result => result).catch(e => e);
        //
        // Promise.all([p1, p2])
        // .then(result => console.log(result))
        // .catch(e => console.log(e));
        // 控制台打印的结果
        // (2) ["ok", Error: 报错了]

        // const p1 = new Promise((resolve, reject) => {
        //   resolve('ok');
        // }).then(result => result).catch(e => e);
        //
        // const p2 = new Promise((resolve, reject) => {
        //   throw new Error('报错了');
        // }).then(result => result);
        //
        // Promise.all([p1, p2])
        // .then(result => console.log(result))
        // .catch(e => console.log(e));
        // 控制台打印的结果
        // Error: 报错了




      }
    </script>
  </body>
</html>
